<?xml version="1.0"?>
<robot xmlns:xacro="http://www.ros.org/wiki/xacro">
    <xacro:macro name="urdf_args" params="joint_limit_file ur_calibration_file">

        <xacro:property name="joint_limits" value="${xacro.load_yaml(joint_limit_file)}"/>
        <xacro:property name="limit_shoulder" value="${joint_limits['joint_limits']['joint_shoulder_pan']}"/>
        <xacro:property name="limit_upper_arm" value="${joint_limits['joint_limits']['joint_shoulder_lift']}"/>
        <xacro:property name="limit_forearm" value="${joint_limits['joint_limits']['joint_elbow']}"/>
        <xacro:property name="limit_wrist_1" value="${joint_limits['joint_limits']['joint_wrist_1']}"/>
        <xacro:property name="limit_wrist_2" value="${joint_limits['joint_limits']['joint_wrist_2']}"/>
        <xacro:property name="limit_wrist_3" value="${joint_limits['joint_limits']['joint_wrist_3']}"/>

        <xacro:property name="calibration" value="${xacro.load_yaml(ur_calibration_file)}"/>
        <xacro:property name="origin_shoulder" value="${calibration['kinematics']['shoulder']}"/>
        <xacro:property name="origin_upper_arm" value="${calibration['kinematics']['upper_arm']}"/>
        <xacro:property name="origin_forearm" value="${calibration['kinematics']['forearm']}"/>
        <xacro:property name="origin_wrist_1" value="${calibration['kinematics']['wrist_1']}"/>
        <xacro:property name="origin_wrist_2" value="${calibration['kinematics']['wrist_2']}"/>
        <xacro:property name="origin_wrist_3" value="${calibration['kinematics']['wrist_3']}"/>

        <joint name="joint_base" type="fixed">
            <parent link="world" />
            <child link="link_base" />
            <origin xyz="0 0 0" rpy="0 0 0" />
        </joint>
        <link name="link_base">
            <visual>
                <origin xyz="0 0 0" rpy="0 0 ${pi}" />
                <geometry>
                    <mesh filename="file://$(find ros2_robot_ur5e)/meshes/ur5e/visual/base.dae" />
                </geometry>
            </visual>
            <collision>
                <origin xyz="0 0 0" rpy="0 0 ${pi}" />
                <geometry>
                    <mesh filename="file://$(find ros2_robot_ur5e)/meshes/ur5e/collision/base.stl" />
                </geometry>
            </collision>
            <inertial>
                <mass value="4.0" />
                <origin rpy="0 0 0" xyz="0 0 0" />
                <inertia
                    ixx="0.0044333156" ixy="0.0" ixz="0.0"
                    iyy="0.0044333156" iyz="0.0"
                    izz="0.0072" />
            </inertial>
        </link>

        <joint name="joint_shoulder_pan" type="revolute">
            <parent link="link_base" />
            <child link="link_shoulder" />
            <origin xyz="${origin_shoulder['x']} ${origin_shoulder['y']} ${origin_shoulder['z']}" 
                    rpy="${origin_shoulder['roll']} ${origin_shoulder['pitch']} ${origin_shoulder['yaw']}" />
            <axis xyz="0 0 1" />
            <limit lower="${limit_shoulder['min_position']}" upper="${limit_shoulder['max_position']}" 
                   effort="${limit_shoulder['max_effort']}" velocity="${limit_shoulder['max_velocity']}" />
            <dynamics damping="0" friction="0" />
        </joint>
        <link name="link_shoulder">
            <visual>
                <origin xyz="0 0 0" rpy="0 0 ${pi}" />
                <geometry>
                    <mesh filename="file://$(find ros2_robot_ur5e)/meshes/ur5e/visual/shoulder.dae" />
                </geometry>
            </visual>
            <collision>
                <origin xyz="0 0 0" rpy="0 0 ${pi}" />
                <geometry>
                    <mesh filename="file://$(find ros2_robot_ur5e)/meshes/ur5e/collision/shoulder.stl" />
                </geometry>
            </collision>
            <inertial>
                <mass value="3.761" />
                <origin rpy="0.0 0.0 0.0" xyz="0.0 -0.00193 -0.02561" />
                <inertia
                    ixx="0.0102675" ixy="0.0" ixz="0.0"
                    iyy="0.0102675" iyz="0.0"
                    izz="0.00666" />
            </inertial>
        </link>

        <joint name="joint_shoulder_lift" type="revolute">
            <parent link="link_shoulder" />
            <child link="link_upper_arm" />
            <origin xyz="${origin_upper_arm['x']} ${origin_upper_arm['y']} ${origin_upper_arm['z']}" 
                    rpy="${origin_upper_arm['roll']} ${origin_upper_arm['pitch']} ${origin_upper_arm['yaw']}" />
            <axis xyz="0 0 1" />
            <limit lower="${limit_upper_arm['min_position']}" upper="${limit_upper_arm['max_position']}" 
                   effort="${limit_upper_arm['max_effort']}" velocity="${limit_upper_arm['max_velocity']}" />
            <dynamics damping="0" friction="0" />
        </joint>
        <link name="link_upper_arm">
            <visual>
                <origin xyz="0 0 0.138" rpy="${pi/2} 0 ${-pi/2}" />
                <geometry>
                    <mesh filename="file://$(find ros2_robot_ur5e)/meshes/ur5e/visual/upperarm.dae" />
                </geometry>
            </visual>
            <collision>
                <origin xyz="0 0 0.138" rpy="${pi/2} 0 ${-pi/2}" />
                <geometry>
                    <mesh filename="file://$(find ros2_robot_ur5e)/meshes/ur5e/collision/upperarm.stl" />
                </geometry>
            </collision>
            <inertial>
                <mass value="8.058" />
                <origin rpy="0.0 ${pi/2} 0.0" xyz="-0.2125 0.0 0.11336" />
                <inertia
                    ixx="0.13388583542" ixy="0.0" ixz="0.0"
                    iyy="0.13388583542" iyz="0.0"
                    izz="0.0151074" />
            </inertial>
        </link>

        <joint name="joint_elbow" type="revolute">
            <parent link="link_upper_arm" />
            <child link="link_forearm" />
            <origin xyz="${origin_forearm['x']} ${origin_forearm['y']} ${origin_forearm['z']}" 
                    rpy="${origin_forearm['roll']} ${origin_forearm['pitch']} ${origin_forearm['yaw']}" />
            <axis xyz="0 0 1" />
            <limit lower="${limit_forearm['min_position']}" upper="${limit_forearm['max_position']}" 
                   effort="${limit_forearm['max_effort']}" velocity="${limit_forearm['max_velocity']}" />
            <dynamics damping="0" friction="0" />
        </joint>
        <link name="link_forearm">
            <visual>
                <origin xyz="0 0 0.007" rpy="${pi/2} 0 ${-pi/2}" />
                <geometry>
                    <mesh filename="file://$(find ros2_robot_ur5e)/meshes/ur5e/visual/forearm.dae" />
                </geometry>
            </visual>
            <collision>
                <origin xyz="0 0 0.007" rpy="${pi/2} 0 ${-pi/2}" />
                <geometry>
                    <mesh filename="file://$(find ros2_robot_ur5e)/meshes/ur5e/collision/forearm.stl" />
                </geometry>
            </collision>
            <inertial>
                <mass value="2.846" />
                <origin rpy="0.0 ${pi/2} 0.0" xyz="-0.2422 0.0 0.0265" />
                <inertia
                    ixx="0.03120936758" ixy="0.0" ixz="0.0"
                    iyy="0.03120936758" iyz="0.0"
                    izz="0.004095" />
            </inertial>
        </link>

        <joint name="joint_wrist_1" type="revolute">
            <parent link="link_forearm" />
            <child link="link_wrist_1" />
            <origin xyz="${origin_wrist_1['x']} ${origin_wrist_1['y']} ${origin_wrist_1['z']}" 
                    rpy="${origin_wrist_1['roll']} ${origin_wrist_1['pitch']} ${origin_wrist_1['yaw']}" />
            <axis xyz="0 0 1" />
            <limit lower="${limit_wrist_1['min_position']}" upper="${limit_wrist_1['max_position']}" 
                   effort="${limit_wrist_1['max_effort']}" velocity="${limit_wrist_1['max_velocity']}" />
            <dynamics damping="0" friction="0" />
        </joint>
        <link name="link_wrist_1">
            <visual>
                <origin xyz="0 0 -0.127" rpy="${pi/2} 0 0" />
                <geometry>
                    <mesh filename="file://$(find ros2_robot_ur5e)/meshes/ur5e/visual/wrist1.dae" />
                </geometry>
            </visual>
            <collision>
                <origin xyz="0 0 -0.127" rpy="${pi/2} 0 0" />
                <geometry>
                    <mesh filename="file://$(find ros2_robot_ur5e)/meshes/ur5e/collision/wrist1.stl" />
                </geometry>
            </collision>
            <inertial>
                <mass value="1.37" />
                <origin rpy="0.0 0.0 0.0" xyz="0.0 -0.01634 -0.0018" />
                <inertia
                    ixx="0.0025599" ixy="0.0" ixz="0.0"
                    iyy="0.0025599" iyz="0.0"
                    izz="0.0021942" />
            </inertial>
        </link>

        <joint name="joint_wrist_2" type="revolute">
            <parent link="link_wrist_1" />
            <child link="link_wrist_2" />
            <origin xyz="${origin_wrist_2['x']} ${origin_wrist_2['y']} ${origin_wrist_2['z']}" 
                    rpy="${origin_wrist_2['roll']} ${origin_wrist_2['pitch']} ${origin_wrist_2['yaw']}" />
            <axis xyz="0 0 1" />
            <limit lower="${limit_wrist_2['min_position']}" upper="${limit_wrist_2['max_position']}" 
                   effort="${limit_wrist_2['max_effort']}" velocity="${limit_wrist_2['max_velocity']}" />
            <dynamics damping="0" friction="0" />
        </joint>
        <link name="link_wrist_2">
            <visual>
                <origin xyz="0 0 -0.0997" rpy="0 0 0" />
                <geometry>
                    <mesh filename="file://$(find ros2_robot_ur5e)/meshes/ur5e/visual/wrist2.dae" />
                </geometry>
            </visual>
            <collision>
                <origin xyz="0 0 -0.0997" rpy="0 0 0" />
                <geometry>
                    <mesh filename="file://$(find ros2_robot_ur5e)/meshes/ur5e/collision/wrist2.stl" />
                </geometry>
            </collision>
            <inertial>
                <mass value="1.3" />
                <origin rpy="0.0 0.0 0.0" xyz="0.0 0.01634 -0.0018" />
                <inertia
                    ixx="0.0025599" ixy="0.0" ixz="0.0"
                    iyy="0.0025599" iyz="0.0"
                    izz="0.0021942" />
            </inertial>
        </link>

        <joint name="joint_wrist_3" type="revolute">
            <parent link="link_wrist_2" />
            <child link="link_wrist_3" />
            <origin xyz="${origin_wrist_3['x']} ${origin_wrist_3['y']} ${origin_wrist_3['z']}" 
                    rpy="${origin_wrist_3['roll']} ${origin_wrist_3['pitch']} ${origin_wrist_3['yaw']}" />
            <axis xyz="0 0 1" />
            <limit lower="${limit_wrist_3['min_position']}" upper="${limit_wrist_3['max_position']}" 
                   effort="${limit_wrist_3['max_effort']}" velocity="${limit_wrist_3['max_velocity']}" />
            <dynamics damping="0" friction="0" />
        </joint>
        <link name="link_wrist_3">
            <visual>
                <origin xyz="0 0 -0.0989" rpy="${pi/2} 0 0" />
                <geometry>
                    <mesh filename="file://$(find ros2_robot_ur5e)/meshes/ur5e/visual/wrist3.dae" />
                </geometry>
            </visual>
            <collision>
                <origin xyz="0 0 -0.0989" rpy="${pi/2} 0 0" />
                <geometry>
                    <mesh filename="file://$(find ros2_robot_ur5e)/meshes/ur5e/collision/wrist3.stl" />
                </geometry>
            </collision>
            <inertial>
                <mass value="0.365" />
                <origin rpy="0.0 0.0 0.0" xyz="0.0 0.0 -0.001159" />
                <inertia
                    ixx="9.8904140083e-5" ixy="0.0" ixz="0.0"
                    iyy="9.8904140083e-5" iyz="0.0"
                    izz="0.0001321171875" />
            </inertial>
        </link>

        <joint name="joint_ft_frame" type="fixed">
            <parent link="link_wrist_3" />
            <child link="link_ft_frame" />
            <origin xyz="0 0 0" rpy="${pi} 0 0" />
        </joint>
        <link name="link_ft_frame" />

        <joint name="joint_flange" type="fixed">
            <parent link="link_wrist_3" />
            <child link="link_flange" />
            <origin xyz="0 0 0" rpy="0 ${-pi/2} ${-pi/2}" />
        </joint>
        <link name="link_flange" />

        <joint name="joint_tool0" type="fixed">
            <parent link="link_flange" />
            <origin xyz="0 0 0" rpy="${pi/2} 0 ${pi/2}" />
            <child link="link_tool0" />
        </joint>
        <link name="link_tool0" />

    </xacro:macro>

</robot>